Workbook

Sheet January 2025
A1: Sr. No. | B1: User ID | C1: Emp. Name | D1: Mode | E1: Designation | F1: Department | G1: Gross salary | H1: In Hand Salary | I1: PF Employer | J1: ESI Employer | K1: Level Wise
A2: 1 | B2: 1 | C2: Chanda Ji | D2: On record | E2: Eyelet Marker | F2: =_xlfn.XLOOKUP(B2,'February 2025'!B:B,'February 2025'!F:F) -> Manufacturing | G2: 10300 | H2: 9142 | I2: 1170 | J2: 335 | K2: =_xlfn.XLOOKUP(C2,'February 2025'!C:C,'February 2025'!K:K) -> L-9
A3: 2 | B3: 2 | C3: Surendra Bairwa | D3: On record | E3: Executive | F3: Domestic | G3: 20500 | H3: 18870 | I3: 1599 | J3: 667 | K3: =_xlfn.XLOOKUP(C3,'February 2025'!C:C,'February 2025'!K:K) -> L-8
A4: 3 | B4: 3 | C4: Harkesh Kumar Bairwa | D4: On record | E4: Cutting Master | F4: =_xlfn.XLOOKUP(B4,'February 2025'!B:B,'February 2025'!F:F) -> Manufacturing | G4: 27500 | H4: 27500 | I4: 0 | J4: 0 | K4: =_xlfn.XLOOKUP(C4,'February 2025'!C:C,'February 2025'!K:K) -> L-9
A5: 4 | B5: 4 | C5: Mohd. Shoyeb Rangrej | D5: On record | E5: Executive | F5: Domestic | G5: 20625 | H5: 18737.44 | I5: 1877 | J5: 671 | K5: =_xlfn.XLOOKUP(C5,'February 2025'!C:C,'February 2025'!K:K) -> L-6
A6: 5 | B6: 5 | C6: Rizwan Ali Khan | D6: Console | E6: Executive | F6: =_xlfn.XLOOKUP(C6,'[1]January 2025'!$C:$C,'[1]January 2025'!$I:$I,"") -> Domestic | G6: 33200 | H6: 31400 | I6: 1950 | J6: 0 | K6: =_xlfn.XLOOKUP(C6,'February 2025'!C:C,'February 2025'!K:K) -> L-6
A7: 6 | B7: 6 | C7: Tehseenul Islam Siddque | D7: On record | E7: Merchandiser | F7: =_xlfn.XLOOKUP(B7,'February 2025'!B:B,'February 2025'!F:F) -> Admin | G7: 62500 | H7: 62500 | I7: 0 | J7: 0 | K7: =_xlfn.XLOOKUP(C7,'February 2025'!C:C,'February 2025'!K:K) -> L-5
A8: 7 | B8: 7 | C8: Rajendra Prasad Vijay | D8: On record | E8: Senior Accountant | F8: =_xlfn.XLOOKUP(B8,'February 2025'!B:B,'February 2025'!F:F) -> Admin | G8: 48000 | H8: 48000 | I8: 0 | J8: 0 | K8: =_xlfn.XLOOKUP(C8,'February 2025'!C:C,'February 2025'!K:K) -> L-5
A9: 8 | B9: 8 | C9: Pankaj | D9: On record | E9: Final Checker | F9: Manufacturing | G9: 18225 | H9: 16775.8 | I9: 1422 | J9: 593 | K9: L-9
A10: 9 | B10: 9 | C10: Ravi Panchal | D10: On record | E10: SKU checker | F10: =_xlfn.XLOOKUP(B10,'February 2025'!B:B,'February 2025'!F:F) -> Domestic | G10: 14800 | H10: 13613.8 | I10: 1165 | J10: 481 | K10: =_xlfn.XLOOKUP(C10,'February 2025'!C:C,'February 2025'!K:K) -> L-9
A11: 10 | B11: 10 | C11: Chandrakanta Meher | D11: On record | E11: Executive | F11: Manufacturing | G11: 34300 | H11: 34300 | I11: 0 | J11: 0 | K11: L-9
A12: 11 | B12: 11 | C12: Rupesh Kumar Jha | D12: On record | E12: Jr. Accountant | F12: =_xlfn.XLOOKUP(B12,'February 2025'!B:B,'February 2025'!F:F) -> Admin | G12: 22000 | H12: 20200 | I12: 1950 | J12: 0 | K12: =_xlfn.XLOOKUP(C12,'February 2025'!C:C,'February 2025'!K:K) -> L-6
A13: 12 | B13: 16 | C13: Abhishek Saini | D13: On record | E13: HR Manager | F13: =_xlfn.XLOOKUP(B13,'February 2025'!B:B,'February 2025'!F:F) -> Domestic | G13: 29000 | H13: 29000 | I13: 0 | J13: 0 | K13: L-6
A14: 13 | B14: 13 | C14: Lokesh Sharma | D14: On record | E14: Executive | F14: =_xlfn.XLOOKUP(B14,'February 2025'!B:B,'February 2025'!F:F) -> Domestic | G14: 14500 | H14: 13341 | I14: 1138 | J14: 472 | K14: =_xlfn.XLOOKUP(C14,'February 2025'!C:C,'February 2025'!K:K) -> L-7
A15: 14 | B15: 14 | C15: Rajesh Sharma | D15: On record | E15: Office Boy | F15: =_xlfn.XLOOKUP(B15,'February 2025'!B:B,'February 2025'!F:F) -> Office Support | G15: 15400 | H15: 14175.2 | I15: 1201 | J15: 501 | K15: =_xlfn.XLOOKUP(C15,'February 2025'!C:C,'February 2025'!K:K) -> L-10
A16: 15 | B16: 15 | C16: Yashodatt Sharma | D16: On record | E16: Fabric Checker | F16: =_xlfn.XLOOKUP(B16,'February 2025'!B:B,'February 2025'!F:F) -> Manufacturing | G16: 20000 | H16: 18410 | I16: 1560 | J16: 650 | K16: =_xlfn.XLOOKUP(C16,'February 2025'!C:C,'February 2025'!K:K) -> L-9
A17: 16 | B17: 16 | C17: Omprakash Yogi | D17: On record | E17: Checker | F17: =_xlfn.XLOOKUP(B17,'February 2025'!B:B,'February 2025'!F:F) -> Domestic | G17: 14063 | H17: 12775.708 | I17: 1280 | J17: 458 | K17: =_xlfn.XLOOKUP(C17,'February 2025'!C:C,'February 2025'!K:K) -> L-9
A18: 17 | B18: 17 | C18: Naveen Bhaskar | D18: On record | E18: Final Checker | F18: =_xlfn.XLOOKUP(B18,'February 2025'!B:B,'February 2025'!F:F) -> Manufacturing | G18: 17500 | H18: 16108 | I18: 1365 | J18: 569 | K18: =_xlfn.XLOOKUP(C18,'February 2025'!C:C,'February 2025'!K:K) -> L-9
A19: 18 | B19: 18 | C19: Surendra K. Bairwa | D19: On record | E19: Executive | F19: Manufacturing | G19: 17000 | H19: 15648 | I19: 1326 | J19: 553 | K19: L-7
A20: 19 | B20: 19 | C20: Govind Sharma | D20: On record | E20: Checker | F20: =_xlfn.XLOOKUP(B20,'February 2025'!B:B,'February 2025'!F:F) -> Manufacturing | G20: 14000 | H20: 12887 | I20: 1092 | J20: 455 | K20: =_xlfn.XLOOKUP(C20,'February 2025'!C:C,'February 2025'!K:K) -> L-9
A21: 20 | B21: 20 | C21: Naresh Kumar Bairwa | D21: On record | E21: Checker | F21: =_xlfn.XLOOKUP(C21,'[1]January 2025'!$C:$C,'[1]January 2025'!$I:$I,"") -> Manufacturing | G21: 14500 | H21: 13173 | I21: 1320 | J21: 472 | K21: =_xlfn.XLOOKUP(C21,'February 2025'!C:C,'February 2025'!K:K) -> L-9
A22: 21 | B22: 21 | C22: Sonu Bairwa | D22: On record | E22: Supervisior | F22: =_xlfn.XLOOKUP(B22,'February 2025'!B:B,'February 2025'!F:F) -> Manufacturing | G22: 22000 | H22: 20416 | I22: 1716 | J22: 0 | K22: =_xlfn.XLOOKUP(C22,'February 2025'!C:C,'February 2025'!K:K) -> L-8
A23: 22 | B23: 22 | C23: Mohamad Faizal | D23: On record | E23: Manager | F23: =_xlfn.XLOOKUP(B23,'February 2025'!B:B,'February 2025'!F:F) -> Domestic | G23: 68200 | H23: 66400 | I23: 1950 | J23: 0 | K23: L-5
A24: 23 | B24: 23 | C24: Anil Kumar | D24: On record | E24: Cutting Master | F24: Manufacturing | G24: 26000 | H24: 24284 | I24: 1859 | J24: 0 | K24: L-9
A25: 24 | B25: 24 | C25: Ravi Kumar Bairwa (Tatawat) | D25: On record | E25: Executive | F25: =_xlfn.XLOOKUP(B25,'February 2025'!B:B,'February 2025'!F:F) -> Domestic | G25: 14000 | H25: 12702.2 | I25: 1292 | J25: 455 | K25: =_xlfn.XLOOKUP(C25,'February 2025'!C:C,'February 2025'!K:K) -> L-8
A26: 25 | B26: 30 | C26: Chandra Shekhar Sharma | D26: On record | E26: Supervisior | F26: Manufacturing | G26: 28000 | H26: 28000 | I26: 0 | J26: 0 | K26: L-8
A27: 26 | B27: 31 | C27: Nupur Pawar | D27: On record | E27: Textile Designer | F27: D2C | G27: 40000 | H27: 40000 | I27: 0 | J27: 0 | K27: L-6
A28: 27 | B28: 27 | C28: Asim Shoyab Khan | D28: On record | E28: Executive | F28: =_xlfn.XLOOKUP(B28,'February 2025'!B:B,'February 2025'!F:F) -> Domestic | G28: 20625 | H28: 18737.44 | I28: 1877 | J28: 671 | K28: =_xlfn.XLOOKUP(C28,'February 2025'!C:C,'February 2025'!K:K) -> L-6
A29: 28 | B29: 33 | C29: Amit Pareek | D29: On record | E29: Manager | F29: =_xlfn.XLOOKUP(B29,'February 2025'!B:B,'February 2025'!F:F) -> D2C | G29: 80000 | H29: 78200 | I29: 1950 | J29: 0 | K29: L-5
A30: 29 | B30: 29 | C30: Peeyush Pareek | D30: On record | E30: Manager | F30: =_xlfn.XLOOKUP(C30,'[1]January 2025'!$C:$C,'[1]January 2025'!$I:$I,"") -> D2C | G30: 63200 | H30: 61400 | I30: 1950 | J30: 0 | K30: =_xlfn.XLOOKUP(C30,'February 2025'!C:C,'February 2025'!K:K) -> L-5
A31: 30 | B31: 19 | C31: Rahul Yogi | D31: On record | E31: Helper | F31: =_xlfn.XLOOKUP(B31,'February 2025'!B:B,'February 2025'!F:F) -> Manufacturing | G31: 11000 | H31: 9837 | I31: 1170 | J31: 358 | K31: L-10
A32: 31 | B32: 31 | C32: Bheema Ram Bairwa | D32: On record | E32: Computer Operator | F32: Manufacturing | G32: 15000 | H32: 13663 | I32: 1326 | J32: 488 | K32: L-7
A33: 32 | B33: 32 | C33: Shaitan Singh | D33: On record | E33: Supervisior | F33: =_xlfn.XLOOKUP(C33,'[1]January 2025'!$C:$C,'[1]January 2025'!$I:$I,"") -> Manufacturing | G33: 24000 | H33: 24000 | I33: 0 | J33: 0 | K33: =_xlfn.XLOOKUP(C33,'February 2025'!C:C,'February 2025'!K:K) -> L-8
A34: 33 | B34: 33 | C34: Chakshita Maheshwari | D34: On record | E34: Graphic Designer | F34: =_xlfn.XLOOKUP(B34,'February 2025'!B:B,'February 2025'!F:F) -> D2C | G34: 31000 | H34: 31000 | I34: 0 | J34: 0 | K34: =_xlfn.XLOOKUP(C34,'February 2025'!C:C,'February 2025'!K:K) -> L-6
A35: 34 | B35: 37 | C35: Yuvraj Singh Sisodiya | D35: On record | E35: Supervisior | F35: =_xlfn.XLOOKUP(B35,'February 2025'!B:B,'February 2025'!F:F) -> Overseas | G35: 18000 | H35: 16353 | I35: 1638 | J35: 585 | K35: L-8
A36: 35 | B36: 35 | C36: Sumer singh Jatav | D36: On record | E36: Press man | F36: Manufacturing | G36: 13500 | H36: 12264 | I36: 1229 | J36: 439 | K36: L-9
A37: 36 | B37: 39 | C37: Ashok Yogi | D37: On record | E37: Checker | F37: =_xlfn.XLOOKUP(B37,'February 2025'!B:B,'February 2025'!F:F) -> Manufacturing | G37: 12500 | H37: 11356 | I37: 1138 | J37: 407 | K37: L-9
A38: 37 | B38: 37 | C38: Karishma Kaityar | D38: On record | E38: Senior Executive | F38: =_xlfn.XLOOKUP(B38,'February 2025'!B:B,'February 2025'!F:F) -> Overseas | G38: 40000 | H38: 40000 | I38: 0 | J38: 0 | K38: =_xlfn.XLOOKUP(C38,'February 2025'!C:C,'February 2025'!K:K) -> L-6
A39: 38 | B39: 38 | C39: Surajmal Prajapati | D39: On record | E39: Human Resource | F39: =_xlfn.XLOOKUP(B39,'February 2025'!B:B,'February 2025'!F:F) -> Admin | G39: 41000 | H39: 41000 | I39: 0 | J39: 0 | K39: =_xlfn.XLOOKUP(C39,'February 2025'!C:C,'February 2025'!K:K) -> L-5
A40: 39 | B40: 39 | C40: Padmawati | D40: On record | E40: Tailor | F40: =_xlfn.XLOOKUP(B40,'February 2025'!B:B,'February 2025'!F:F) -> Manufacturing | G40: 30000 | H40: 30000 | I40: 0 | J40: 0 | K40: =_xlfn.XLOOKUP(C40,'February 2025'!C:C,'February 2025'!K:K) -> L-9
...

Sheet February 2025
A1: {='January 2025'!A1:K1} -> Sr. No. | B1: User ID | C1: Emp. Name | D1: Mode | E1: Designation | F1: Department | G1: Gross salary | H1: In Hand Salary | I1: PF Employer | J1: ESI Employer | K1: Level Wise
A2: 1 | B2: 1 | C2: Chanda Ji | D2: On record | E2: Eyelet Marker | F2: =_xlfn.XLOOKUP('February 2025'!B2,'March 2025'!B:B,'March 2025'!F:F) -> Manufacturing | G2: 10300 | H2: 9142 | I2: 1170 | J2: 335 | K2: =_xlfn.XLOOKUP(C2,'March 2025'!C:C,'March 2025'!K:K) -> L-9
A3: 2 | B3: 2 | C3: Surendra Bairwa | D3: On record | E3: Executive | F3: =_xlfn.XLOOKUP(C3,'[1]February 2025'!$C:$C,'[1]February 2025'!$I:$I) -> Domestic | G3: 20500 | H3: 18870 | I3: 1599 | J3: 667 | K3: =_xlfn.XLOOKUP(C3,'March 2025'!C:C,'March 2025'!K:K) -> L-8
A4: 3 | B4: 3 | C4: Harkesh Kumar Bairwa | D4: On record | E4: Cutting Master | F4: =_xlfn.XLOOKUP('February 2025'!B4,'March 2025'!B:B,'March 2025'!F:F) -> Manufacturing | G4: 27500 | H4: 27500 | I4: 0 | J4: 0 | K4: =_xlfn.XLOOKUP(C4,'March 2025'!C:C,'March 2025'!K:K) -> L-9
A5: 4 | B5: 4 | C5: Mohd. Shoyeb Rangrej | D5: On record | E5: Executive | F5: =_xlfn.XLOOKUP(C5,'[1]February 2025'!$C:$C,'[1]February 2025'!$I:$I) -> Domestic | G5: 20625 | H5: 18737.44 | I5: 1877 | J5: 671 | K5: =_xlfn.XLOOKUP(C5,'March 2025'!C:C,'March 2025'!K:K) -> L-6
A6: 5 | B6: 5 | C6: Rizwan Ali Khan | D6: Console | E6: Executive | F6: =_xlfn.XLOOKUP(C6,'[1]February 2025'!$C:$C,'[1]February 2025'!$I:$I) -> Domestic | G6: 33200 | H6: 31400 | I6: 1950 | J6: 0 | K6: =_xlfn.XLOOKUP(C6,'March 2025'!C:C,'March 2025'!K:K) -> L-6
A7: 6 | B7: 6 | C7: Tehseenul Islam Siddque | D7: On record | E7: Merchandiser | F7: =_xlfn.XLOOKUP('February 2025'!B7,'March 2025'!B:B,'March 2025'!F:F) -> Admin | G7: 62500 | H7: 62500 | I7: 0 | J7: 0 | K7: =_xlfn.XLOOKUP(C7,'March 2025'!C:C,'March 2025'!K:K) -> L-5
A8: 7 | B8: 7 | C8: Rajendra Prasad Vijay | D8: On record | E8: Senior Accountant | F8: =_xlfn.XLOOKUP('February 2025'!B8,'March 2025'!B:B,'March 2025'!F:F) -> Admin | G8: 48000 | H8: 48000 | I8: 0 | J8: 0 | K8: =_xlfn.XLOOKUP(C8,'March 2025'!C:C,'March 2025'!K:K) -> L-5
A9: 8 | B9: 9 | C9: Ravi Panchal | D9: On record | E9: SKU checker | F9: =_xlfn.XLOOKUP('February 2025'!B9,'March 2025'!B:B,'March 2025'!F:F) -> Domestic | G9: 14800 | H9: 13613.8 | I9: 1165 | J9: 481 | K9: =_xlfn.XLOOKUP(C9,'March 2025'!C:C,'March 2025'!K:K) -> L-9
A10: 9 | B10: 11 | C10: Rupesh Kumar Jha | D10: On record | E10: Jr. Accountant | F10: =_xlfn.XLOOKUP('February 2025'!B10,'March 2025'!B:B,'March 2025'!F:F) -> Admin | G10: 22000 | H10: 20200 | I10: 1950 | J10: 0 | K10: =_xlfn.XLOOKUP(C10,'March 2025'!C:C,'March 2025'!K:K) -> L-6
A11: 10 | B11: 13 | C11: Lokesh Sharma | D11: On record | E11: Executive | F11: =_xlfn.XLOOKUP('February 2025'!B11,'March 2025'!B:B,'March 2025'!F:F) -> Domestic | G11: 14500 | H11: 13341 | I11: 1138 | J11: 472 | K11: =_xlfn.XLOOKUP(C11,'March 2025'!C:C,'March 2025'!K:K) -> L-7
A12: 11 | B12: 14 | C12: Rajesh Sharma | D12: On record | E12: Office Boy | F12: =_xlfn.XLOOKUP('February 2025'!B12,'March 2025'!B:B,'March 2025'!F:F) -> Office Support | G12: 15400 | H12: 14175.2 | I12: 1201 | J12: 501 | K12: =_xlfn.XLOOKUP(C12,'March 2025'!C:C,'March 2025'!K:K) -> L-10
A13: 12 | B13: 15 | C13: Yashodatt Sharma | D13: On record | E13: Fabric Checker | F13: =_xlfn.XLOOKUP('February 2025'!B13,'March 2025'!B:B,'March 2025'!F:F) -> Manufacturing | G13: 20000 | H13: 18410 | I13: 1560 | J13: 650 | K13: =_xlfn.XLOOKUP(C13,'March 2025'!C:C,'March 2025'!K:K) -> L-9
A14: 13 | B14: 16 | C14: Omprakash Yogi | D14: On record | E14: Checker | F14: =_xlfn.XLOOKUP('February 2025'!B14,'March 2025'!B:B,'March 2025'!F:F) -> Domestic | G14: 14063 | H14: 12775.708 | I14: 1280 | J14: 458 | K14: =_xlfn.XLOOKUP(C14,'March 2025'!C:C,'March 2025'!K:K) -> L-9
A15: 14 | B15: 17 | C15: Naveen Bhaskar | D15: On record | E15: Final Checker | F15: =_xlfn.XLOOKUP('February 2025'!B15,'March 2025'!B:B,'March 2025'!F:F) -> Manufacturing | G15: 17500 | H15: 16108 | I15: 1365 | J15: 569 | K15: =_xlfn.XLOOKUP(C15,'March 2025'!C:C,'March 2025'!K:K) -> L-9
A16: 15 | B16: 19 | C16: Govind Sharma | D16: On record | E16: Checker | F16: =_xlfn.XLOOKUP('February 2025'!B16,'March 2025'!B:B,'March 2025'!F:F) -> Manufacturing | G16: 14000 | H16: 12887 | I16: 1092 | J16: 455 | K16: =_xlfn.XLOOKUP(C16,'March 2025'!C:C,'March 2025'!K:K) -> L-9
A17: 16 | B17: 20 | C17: Naresh Kumar Bairwa | D17: On record | E17: Checker | F17: =_xlfn.XLOOKUP(C17,'[1]February 2025'!$C:$C,'[1]February 2025'!$I:$I) -> Manufacturing | G17: 14500 | H17: 13173 | I17: 1320 | J17: 472 | K17: =_xlfn.XLOOKUP(C17,'March 2025'!C:C,'March 2025'!K:K) -> L-9
A18: 17 | B18: 21 | C18: Sonu Bairwa | D18: On record | E18: Supervisior | F18: =_xlfn.XLOOKUP('February 2025'!B18,'March 2025'!B:B,'March 2025'!F:F) -> Manufacturing | G18: 22000 | H18: 20416 | I18: 1716 | J18: 0 | K18: =_xlfn.XLOOKUP(C18,'March 2025'!C:C,'March 2025'!K:K) -> L-8
A19: 18 | B19: 22 | C19: Mohamad Faizal | D19: On record | E19: Manager | F19: =_xlfn.XLOOKUP('February 2025'!B19,'March 2025'!B:B,'March 2025'!F:F) -> Domestic | G19: 68200 | H19: 66400 | I19: 1950 | J19: 0 | K19: L-5
A20: 19 | B20: 24 | C20: Ravi Kumar Bairwa (Tatawat) | D20: On record | E20: Executive | F20: =_xlfn.XLOOKUP('February 2025'!B20,'March 2025'!B:B,'March 2025'!F:F) -> Domestic | G20: 14000 | H20: 12702.2 | I20: 1292 | J20: 455 | K20: =_xlfn.XLOOKUP(C20,'March 2025'!C:C,'March 2025'!K:K) -> L-8
A21: 20 | B21: 27 | C21: Asim Shoyab Khan | D21: On record | E21: Executive | F21: =_xlfn.XLOOKUP('February 2025'!B21,'March 2025'!B:B,'March 2025'!F:F) -> Domestic | G21: 20625 | H21: 18737.44 | I21: 1877 | J21: 671 | K21: =_xlfn.XLOOKUP(C21,'March 2025'!C:C,'March 2025'!K:K) -> L-6
A22: 21 | B22: 29 | C22: Peeyush Pareek | D22: On record | E22: Manager | F22: =_xlfn.XLOOKUP(C22,'[1]February 2025'!$C:$C,'[1]February 2025'!$I:$I) -> D2C | G22: 79450 | H22: 77650 | I22: 1950 | J22: 0 | K22: =_xlfn.XLOOKUP(C22,'March 2025'!C:C,'March 2025'!K:K) -> L-5
A23: 22 | B23: 32 | C23: Shaitan Singh | D23: On record | E23: Supervisior | F23: =_xlfn.XLOOKUP(C23,'[1]February 2025'!$C:$C,'[1]February 2025'!$I:$I) -> Manufacturing | G23: 24000 | H23: 24000 | I23: 0 | J23: 0 | K23: =_xlfn.XLOOKUP(C23,'March 2025'!C:C,'March 2025'!K:K) -> L-8
A24: 23 | B24: 33 | C24: Chakshita Maheshwari | D24: On record | E24: Graphic Designer | F24: =_xlfn.XLOOKUP('February 2025'!B24,'March 2025'!B:B,'March 2025'!F:F) -> D2C | G24: 31000 | H24: 31000 | I24: 0 | J24: 0 | K24: =_xlfn.XLOOKUP(C24,'March 2025'!C:C,'March 2025'!K:K) -> L-6
A25: 24 | B25: 37 | C25: Karishma Kaityar | D25: On record | E25: Senior Executive | F25: =_xlfn.XLOOKUP('February 2025'!B25,'March 2025'!B:B,'March 2025'!F:F) -> Overseas | G25: 40000 | H25: 40000 | I25: 0 | J25: 0 | K25: =_xlfn.XLOOKUP(C25,'March 2025'!C:C,'March 2025'!K:K) -> L-6
A26: 25 | B26: 38 | C26: Surajmal Prajapati | D26: On record | E26: Human Resource | F26: =_xlfn.XLOOKUP('February 2025'!B26,'March 2025'!B:B,'March 2025'!F:F) -> Admin | G26: 41000 | H26: 41000 | I26: 0 | J26: 0 | K26: =_xlfn.XLOOKUP(C26,'March 2025'!C:C,'March 2025'!K:K) -> L-5
A27: 26 | B27: 39 | C27: Padmawati | D27: On record | E27: Tailor | F27: =_xlfn.XLOOKUP('February 2025'!B27,'March 2025'!B:B,'March 2025'!F:F) -> Manufacturing | G27: 30000 | H27: 30000 | I27: 0 | J27: 0 | K27: =_xlfn.XLOOKUP(C27,'March 2025'!C:C,'March 2025'!K:K) -> L-9
A28: 27 | B28: 40 | C28: Foranti | D28: On record | E28: 0.71944444 | F28: =_xlfn.XLOOKUP(C28,'[1]February 2025'!$C:$C,'[1]February 2025'!$I:$I) -> Manufacturing | G28: 30000 | H28: 30000 | I28: 0 | J28: 0 | K28: =_xlfn.XLOOKUP(C28,'March 2025'!C:C,'March 2025'!K:K) -> L-9
A29: 28 | B29: 41 | C29: Sonu Bairwa Tailor | D29: On record | E29: Tailor | F29: =_xlfn.XLOOKUP('February 2025'!B29,'March 2025'!B:B,'March 2025'!F:F) -> Manufacturing | G29: 30000 | H29: 30000 | I29: 0 | J29: 0 | K29: =_xlfn.XLOOKUP(C29,'March 2025'!C:C,'March 2025'!K:K) -> L-9
A30: 29 | B30: 42 | C30: Raji Devi | D30: On record | E30: Tailor | F30: =_xlfn.XLOOKUP('February 2025'!B30,'March 2025'!B:B,'March 2025'!F:F) -> Manufacturing | G30: 30000 | H30: 30000 | I30: 0 | J30: 0 | K30: =_xlfn.XLOOKUP(C30,'March 2025'!C:C,'March 2025'!K:K) -> L-9
A31: 30 | B31: 43 | C31: Laxman | D31: On record | E31: Tailor | F31: =_xlfn.XLOOKUP('February 2025'!B31,'March 2025'!B:B,'March 2025'!F:F) -> Manufacturing | G31: 30000 | H31: 30000 | I31: 0 | J31: 0 | K31: =_xlfn.XLOOKUP(C31,'March 2025'!C:C,'March 2025'!K:K) -> L-9
A32: 31 | B32: 44 | C32: Dilip | D32: On record | E32: Tailor | F32: =_xlfn.XLOOKUP('February 2025'!B32,'March 2025'!B:B,'March 2025'!F:F) -> Manufacturing | G32: 30000 | H32: 30000 | I32: 0 | J32: 0 | K32: =_xlfn.XLOOKUP(C32,'March 2025'!C:C,'March 2025'!K:K) -> L-9
A33: 32 | B33: 46 | C33: Furqan Hameed | D33: On record | E33: Manager | F33: =_xlfn.XLOOKUP('February 2025'!B33,'March 2025'!B:B,'March 2025'!F:F) -> Overseas | G33: 80000 | H33: 80000 | I33: 0 | J33: 0 | K33: =_xlfn.XLOOKUP(C33,'March 2025'!C:C,'March 2025'!K:K) -> L-5
A34: 33 | B34: 47 | C34: Riddhi Gupta | D34: On record | E34: Customer Relatioship Executive | F34: =_xlfn.XLOOKUP('February 2025'!B34,'March 2025'!B:B,'March 2025'!F:F) -> D2C | G34: 19000 | H34: 18857 | I34: 0 | J34: 618 | K34: l-6
A35: 34 | B35: 48 | C35: Safina Khan | D35: On record | E35: Tailor | F35: =_xlfn.XLOOKUP('February 2025'!B35,'March 2025'!B:B,'March 2025'!F:F) -> Manufacturing | G35: 30000 | H35: 30000 | I35: 0 | J35: 0 | K35: =_xlfn.XLOOKUP(C35,'March 2025'!C:C,'March 2025'!K:K) -> L-9
A36: 35 | B36: 49 | C36: Gulbatti Meena | D36: On record | E36: Tailor | F36: =_xlfn.XLOOKUP(C36,'[1]February 2025'!$C:$C,'[1]February 2025'!$I:$I) -> Manufacturing | G36: 30000 | H36: 30000 | I36: 0 | J36: 0 | K36: =_xlfn.XLOOKUP(C36,'March 2025'!C:C,'March 2025'!K:K) -> L-9
A37: 36 | B37: 10002 | C37: Manish Kumar Bairwa | D37: Console | E37: Press man | F37: =_xlfn.XLOOKUP('February 2025'!B37,'March 2025'!B:B,'March 2025'!F:F) -> Domestic | G37: 14000 | H37: 14000 | I37: 0 | J37: 0 | K37: =_xlfn.XLOOKUP(C37,'March 2025'!C:C,'March 2025'!K:K) -> L-10
A38: 37 | B38: 10004 | C38: Ramswaroop | D38: Console | E38: Final Checker | F38: =_xlfn.XLOOKUP('February 2025'!B38,'March 2025'!B:B,'March 2025'!F:F) -> Manufacturing | G38: 15000 | H38: 15000 | I38: 0 | J38: 0 | K38: =_xlfn.XLOOKUP(C38,'March 2025'!C:C,'March 2025'!K:K) -> L-9
A39: 38 | B39: 10005 | C39: Chhaju Lal Saini | D39: Console | E39: Computer Operator | F39: =_xlfn.XLOOKUP('February 2025'!B39,'March 2025'!B:B,'March 2025'!F:F) -> Manufacturing | G39: 16000 | H39: 16000 | I39: 0 | J39: 0 | K39: =_xlfn.XLOOKUP(C39,'March 2025'!C:C,'March 2025'!K:K) -> L-8
A40: 39 | B40: 10006 | C40: Mahendra Gurjer | D40: Console | E40: Cutting Master | F40: =_xlfn.XLOOKUP('February 2025'!B40,'March 2025'!B:B,'March 2025'!F:F) -> Manufacturing | G40: 16000 | H40: 16000 | I40: 0 | J40: 0 | K40: =_xlfn.XLOOKUP(C40,'March 2025'!C:C,'March 2025'!K:K) -> L-9
...

Sheet March 2025
A1: Sr. No. | B1: User ID | C1: Emp. Name | D1: Mode | E1: Designation | F1: Department | G1: Gross salary | H1: In Hand Salary | I1: PF Employer | J1: ESI Employer | K1: Level Wise
A2: 1 | B2: 1 | C2: Chanda Ji | D2: On record | E2: Eyelet Marker | F2: =_xlfn.XLOOKUP(B2,'April 2025'!B:B,'April 2025'!F:F) -> Manufacturing | G2: 10300 | H2: 9142 | I2: 1170 | J2: 335 | K2: =_xlfn.XLOOKUP(C2,'April 2025'!C:C,'April 2025'!K:K) -> L-9
A3: 2 | B3: 2 | C3: Surendra Bairwa | D3: On record | E3: Executive | F3: =_xlfn.XLOOKUP(B3,'April 2025'!B:B,'April 2025'!F:F) -> Domestic | G3: 20500 | H3: 18870 | I3: 1599 | J3: 667 | K3: =_xlfn.XLOOKUP(C3,'April 2025'!C:C,'April 2025'!K:K) -> L-8
A4: 3 | B4: 3 | C4: Harkesh Kumar Bairwa | D4: On record | E4: Cutting Master | F4: =_xlfn.XLOOKUP(B4,'April 2025'!B:B,'April 2025'!F:F) -> Manufacturing | G4: 27500 | H4: 27500 | I4: 0 | J4: 0 | K4: =_xlfn.XLOOKUP(C4,'April 2025'!C:C,'April 2025'!K:K) -> L-9
A5: 4 | B5: 4 | C5: Mohd. Shoyeb Rangrej | D5: On record | E5: Executive | F5: =_xlfn.XLOOKUP(B5,'April 2025'!B:B,'April 2025'!F:F) -> Domestic | G5: 20625 | H5: 18737.44 | I5: 1877 | J5: 671 | K5: =_xlfn.XLOOKUP(C5,'April 2025'!C:C,'April 2025'!K:K) -> L-6
A6: 5 | B6: 5 | C6: Rizwan Ali Khan | D6: Console | E6: Executive | F6: =_xlfn.XLOOKUP(B6,'April 2025'!B:B,'April 2025'!F:F) -> Domestic | G6: 33200 | H6: 31400 | I6: 1950 | J6: 0 | K6: =_xlfn.XLOOKUP(C6,'April 2025'!C:C,'April 2025'!K:K) -> L-6
A7: 6 | B7: 6 | C7: Tehseenul Islam Siddque | D7: On record | E7: Merchandiser | F7: =_xlfn.XLOOKUP(B7,'April 2025'!B:B,'April 2025'!F:F) -> Admin | G7: 62500 | H7: 62500 | I7: 0 | J7: 0 | K7: =_xlfn.XLOOKUP(C7,'April 2025'!C:C,'April 2025'!K:K) -> L-5
A8: 7 | B8: 7 | C8: Rajendra Prasad Vijay | D8: On record | E8: Senior Accountant | F8: =_xlfn.XLOOKUP(B8,'April 2025'!B:B,'April 2025'!F:F) -> Admin | G8: 48000 | H8: 48000 | I8: 0 | J8: 0 | K8: =_xlfn.XLOOKUP(C8,'April 2025'!C:C,'April 2025'!K:K) -> L-5
A9: 8 | B9: 8 | C9: Pankaj | D9: On record | E9: Final Checker | F9: =_xlfn.XLOOKUP(C9,'January 2025'!C:C,'January 2025'!F:F) -> Manufacturing | G9: 18225 | H9: 16775.8 | I9: 1422 | J9: 593 | K9: L-9
A10: 9 | B10: 9 | C10: Ravi Panchal | D10: On record | E10: SKU checker | F10: =_xlfn.XLOOKUP(B10,'April 2025'!B:B,'April 2025'!F:F) -> Domestic | G10: 14800 | H10: 13613.8 | I10: 1165 | J10: 481 | K10: =_xlfn.XLOOKUP(C10,'April 2025'!C:C,'April 2025'!K:K) -> L-9
A11: 10 | B11: 10 | C11: Chandrakanta Meher | D11: On record | E11: Executive | F11: =_xlfn.XLOOKUP(C11,'January 2025'!C:C,'January 2025'!F:F) -> Manufacturing | G11: 34300 | H11: 34300 | I11: 0 | J11: 0 | K11: L-8
A12: 11 | B12: 11 | C12: Rupesh Kumar Jha | D12: On record | E12: Jr. Accountant | F12: =_xlfn.XLOOKUP(B12,'April 2025'!B:B,'April 2025'!F:F) -> Admin | G12: 22000 | H12: 20200 | I12: 1950 | J12: 0 | K12: =_xlfn.XLOOKUP(C12,'April 2025'!C:C,'April 2025'!K:K) -> L-6
A13: 12 | B13: 16 | C13: Abhishek Saini | D13: On record | E13: HR Manager | F13: =_xlfn.XLOOKUP(B13,'April 2025'!B:B,'April 2025'!F:F) -> Domestic | G13: 29000 | H13: 29000 | I13: 0 | J13: 0 | K13: =_xlfn.XLOOKUP(C13,'April 2025'!C:C,'April 2025'!K:K) -> L-9
A14: 13 | B14: 13 | C14: Lokesh Sharma | D14: On record | E14: Executive | F14: =_xlfn.XLOOKUP(B14,'April 2025'!B:B,'April 2025'!F:F) -> Domestic | G14: 14500 | H14: 13341 | I14: 1138 | J14: 472 | K14: =_xlfn.XLOOKUP(C14,'April 2025'!C:C,'April 2025'!K:K) -> L-7
A15: 14 | B15: 14 | C15: Rajesh Sharma | D15: On record | E15: Office Boy | F15: =_xlfn.XLOOKUP(B15,'April 2025'!B:B,'April 2025'!F:F) -> Office Support | G15: 15400 | H15: 14175.2 | I15: 1201 | J15: 501 | K15: =_xlfn.XLOOKUP(C15,'April 2025'!C:C,'April 2025'!K:K) -> L-10
A16: 15 | B16: 15 | C16: Yashodatt Sharma | D16: On record | E16: Fabric Checker | F16: =_xlfn.XLOOKUP(B16,'April 2025'!B:B,'April 2025'!F:F) -> Manufacturing | G16: 20000 | H16: 18410 | I16: 1560 | J16: 650 | K16: =_xlfn.XLOOKUP(C16,'April 2025'!C:C,'April 2025'!K:K) -> L-9
A17: 16 | B17: 16 | C17: Omprakash Yogi | D17: On record | E17: Checker | F17: =_xlfn.XLOOKUP(B17,'April 2025'!B:B,'April 2025'!F:F) -> Domestic | G17: 14063 | H17: 12775.708 | I17: 1280 | J17: 458 | K17: =_xlfn.XLOOKUP(C17,'April 2025'!C:C,'April 2025'!K:K) -> L-9
A18: 17 | B18: 17 | C18: Naveen Bhaskar | D18: On record | E18: Final Checker | F18: =_xlfn.XLOOKUP(B18,'April 2025'!B:B,'April 2025'!F:F) -> Manufacturing | G18: 17500 | H18: 16108 | I18: 1365 | J18: 569 | K18: =_xlfn.XLOOKUP(C18,'April 2025'!C:C,'April 2025'!K:K) -> L-9
A19: 18 | B19: 18 | C19: Surendra K. Bairwa | D19: On record | E19: Executive | F19: =_xlfn.XLOOKUP(C19,'January 2025'!C:C,'January 2025'!F:F) -> Manufacturing | G19: 17000 | H19: 15648 | I19: 1326 | J19: 553 | K19: L-8
A20: 19 | B20: 19 | C20: Govind Sharma | D20: On record | E20: Checker | F20: =_xlfn.XLOOKUP(B20,'April 2025'!B:B,'April 2025'!F:F) -> Manufacturing | G20: 15300 | H20: 14083.4 | I20: 1193 | J20: 498 | K20: =_xlfn.XLOOKUP(C20,'April 2025'!C:C,'April 2025'!K:K) -> L-9
A21: 20 | B21: 20 | C21: Naresh Kumar Bairwa | D21: On record | E21: Checker | F21: =_xlfn.XLOOKUP(B21,'April 2025'!B:B,'April 2025'!F:F) -> Manufacturing | G21: 14500 | H21: 13173 | I21: 1320 | J21: 472 | K21: =_xlfn.XLOOKUP(C21,'April 2025'!C:C,'April 2025'!K:K) -> L-9
A22: 21 | B22: 21 | C22: Sonu Bairwa | D22: On record | E22: Supervisior | F22: =_xlfn.XLOOKUP(B22,'April 2025'!B:B,'April 2025'!F:F) -> Manufacturing | G22: 22000 | H22: 20416 | I22: 1716 | J22: 0 | K22: =_xlfn.XLOOKUP(C22,'April 2025'!C:C,'April 2025'!K:K) -> L-8
A23: 22 | B23: 22 | C23: Faizal Rangrej | D23: On record | E23: Manager | F23: =_xlfn.XLOOKUP(B23,'April 2025'!B:B,'April 2025'!F:F) -> Domestic | G23: 68200 | H23: 66400 | I23: 1950 | J23: 0 | K23: =_xlfn.XLOOKUP(C23,'April 2025'!C:C,'April 2025'!K:K) -> L-5
A24: 23 | B24: 23 | C24: Anil Kumar | D24: On record | E24: Cutting Master | F24: =_xlfn.XLOOKUP(C24,'January 2025'!C:C,'January 2025'!F:F) -> Manufacturing | G24: 26000 | H24: 24284 | I24: 1859 | J24: 0 | K24: L-9
A25: 24 | B25: 24 | C25: Ravi Kumar Bairwa (Tatawat) | D25: On record | E25: Executive | F25: =_xlfn.XLOOKUP(B25,'April 2025'!B:B,'April 2025'!F:F) -> Domestic | G25: 14000 | H25: 12702.2 | I25: 1292 | J25: 455 | K25: =_xlfn.XLOOKUP(C25,'April 2025'!C:C,'April 2025'!K:K) -> L-8
A26: 25 | B26: 30 | C26: Chandra Shekhar Sharma | D26: On record | E26: Supervisior | F26: =_xlfn.XLOOKUP(C26,'January 2025'!C:C,'January 2025'!F:F) -> Manufacturing | G26: 28000 | H26: 28000 | I26: 0 | J26: 0 | K26: L-8
A27: 26 | B27: 31 | C27: Nupur Pawar | D27: On record | E27: Textile Designer | F27: =_xlfn.XLOOKUP(C27,'January 2025'!C:C,'January 2025'!F:F) -> D2C | G27: 40000 | H27: 40000 | I27: 0 | J27: 0 | K27: L-6
A28: 27 | B28: 27 | C28: Asim Shoyab Khan | D28: On record | E28: Executive | F28: =_xlfn.XLOOKUP(B28,'April 2025'!B:B,'April 2025'!F:F) -> Domestic | G28: 20625 | H28: 18737.44 | I28: 1877 | J28: 671 | K28: =_xlfn.XLOOKUP(C28,'April 2025'!C:C,'April 2025'!K:K) -> L-6
A29: 28 | B29: 33 | C29: Amit Pareek | D29: On record | E29: Manager | F29: =_xlfn.XLOOKUP(B29,'April 2025'!B:B,'April 2025'!F:F) -> D2C | G29: 80000 | H29: 78200 | I29: 1950 | J29: 0 | K29: =_xlfn.XLOOKUP(C29,'April 2025'!C:C,'April 2025'!K:K) -> L-6
A30: 29 | B30: 29 | C30: Peeyush Pareek | D30: On record | E30: Manager | F30: =_xlfn.XLOOKUP(B30,'April 2025'!B:B,'April 2025'!F:F) -> D2C | G30: 79450 | H30: 77650 | I30: 1950 | J30: 0 | K30: =_xlfn.XLOOKUP(C30,'April 2025'!C:C,'April 2025'!K:K) -> L-5
A31: 30 | B31: 19 | C31: Rahul Yogi | D31: On record | E31: Helper | F31: =_xlfn.XLOOKUP(B31,'April 2025'!B:B,'April 2025'!F:F) -> Manufacturing | G31: 11000 | H31: 9837 | I31: 1170 | J31: 358 | K31: =_xlfn.XLOOKUP(C31,'April 2025'!C:C,'April 2025'!K:K) -> L-9
A32: 31 | B32: 31 | C32: Bheema Ram Bairwa | D32: On record | E32: Computer Operator | F32: =_xlfn.XLOOKUP(C32,'January 2025'!C:C,'January 2025'!F:F) -> Manufacturing | G32: 15000 | H32: 13663 | I32: 1326 | J32: 488 | K32: L-7
A33: 32 | B33: 32 | C33: Shaitan Singh | D33: On record | E33: Supervisior | F33: =_xlfn.XLOOKUP(B33,'April 2025'!B:B,'April 2025'!F:F) -> Manufacturing | G33: 25000 | H33: 25000 | I33: 0 | J33: 0 | K33: =_xlfn.XLOOKUP(C33,'April 2025'!C:C,'April 2025'!K:K) -> L-8
A34: 33 | B34: 33 | C34: Chakshita Maheshwari | D34: On record | E34: Graphic Designer | F34: =_xlfn.XLOOKUP(B34,'April 2025'!B:B,'April 2025'!F:F) -> D2C | G34: 31000 | H34: 31000 | I34: 0 | J34: 0 | K34: =_xlfn.XLOOKUP(C34,'April 2025'!C:C,'April 2025'!K:K) -> L-6
A35: 34 | B35: 37 | C35: Yuvraj Singh Sisodiya | D35: On record | E35: Supervisior | F35: =_xlfn.XLOOKUP(B35,'April 2025'!B:B,'April 2025'!F:F) -> Overseas | G35: 18000 | H35: 16353 | I35: 1638 | J35: 585 | K35: =_xlfn.XLOOKUP(C35,'April 2025'!C:C,'April 2025'!K:K) -> L-6
A36: 35 | B36: 35 | C36: Sumer singh Jatav | D36: On record | E36: Press man | F36: =_xlfn.XLOOKUP(C36,'January 2025'!C:C,'January 2025'!F:F) -> Manufacturing | G36: 13500 | H36: 12264 | I36: 1229 | J36: 439 | K36: L-9
A37: 36 | B37: 39 | C37: Ashok Yogi | D37: On record | E37: Checker | F37: =_xlfn.XLOOKUP(B37,'April 2025'!B:B,'April 2025'!F:F) -> Manufacturing | G37: 12500 | H37: 11356 | I37: 1138 | J37: 407 | K37: =_xlfn.XLOOKUP(C37,'April 2025'!C:C,'April 2025'!K:K) -> L-9
A38: 37 | B38: 37 | C38: Karishma Kaityar | D38: On record | E38: Senior Executive | F38: =_xlfn.XLOOKUP(B38,'April 2025'!B:B,'April 2025'!F:F) -> Overseas | G38: 40000 | H38: 40000 | I38: 0 | J38: 0 | K38: =_xlfn.XLOOKUP(C38,'April 2025'!C:C,'April 2025'!K:K) -> L-6
A39: 38 | B39: 38 | C39: Surajmal Prajapati | D39: On record | E39: Human Resource | F39: =_xlfn.XLOOKUP(B39,'April 2025'!B:B,'April 2025'!F:F) -> Admin | G39: 41000 | H39: 41000 | I39: 0 | J39: 0 | K39: =_xlfn.XLOOKUP(C39,'April 2025'!C:C,'April 2025'!K:K) -> L-5
A40: 39 | B40: 39 | C40: Padmawati | D40: On record | E40: Tailor | F40: =_xlfn.XLOOKUP(B40,'April 2025'!B:B,'April 2025'!F:F) -> Manufacturing | G40: 30000 | H40: 30000 | I40: 0 | J40: 0 | K40: =_xlfn.XLOOKUP(C40,'April 2025'!C:C,'April 2025'!K:K) -> L-9
...

Sheet April 2025
A1: Sr. No. | B1: User ID | C1: Emp. Name | D1: Mode | E1: Designation | F1: Department | G1: Gross salary | H1: In Hand Salary | I1: PF Employer | J1: ESI Employer | K1: Level Wise
A2: 1 | B2: 1 | C2: Chanda Ji | D2: On record | E2: Eyelet Marker | F2: =_xlfn.XLOOKUP(B2,'May 2025'!B:B,'June 2025'!F:F) -> Manufacturing | G2: 10300 | H2: 9142 | I2: 1170 | J2: 335 | K2: =_xlfn.XLOOKUP(B2,'May 2025'!B:B,'May 2025'!K:K) -> L-9
A3: 2 | B3: 2 | C3: Surendra Bairwa | D3: On record | E3: Executive | F3: =_xlfn.XLOOKUP(B3,'May 2025'!B:B,'June 2025'!F:F) -> Domestic | G3: 20500 | H3: 18870 | I3: 1599 | J3: 667 | K3: =_xlfn.XLOOKUP(B3,'May 2025'!B:B,'May 2025'!K:K) -> L-8
A4: 3 | B4: 3 | C4: Harkesh Kumar Bairwa | D4: On record | E4: Cutting Master | F4: =_xlfn.XLOOKUP(B4,'May 2025'!B:B,'June 2025'!F:F) -> Manufacturing | G4: 27500 | H4: 27500 | I4: 0 | J4: 0 | K4: =_xlfn.XLOOKUP(B4,'May 2025'!B:B,'May 2025'!K:K) -> L-9
A5: 4 | B5: 4 | C5: Mohd. Shoyeb Rangrej | D5: On record | E5: Executive | F5: =_xlfn.XLOOKUP(B5,'May 2025'!B:B,'June 2025'!F:F) -> Domestic | G5: 20625 | H5: 18737.44 | I5: 1877 | J5: 671 | K5: =_xlfn.XLOOKUP(B5,'May 2025'!B:B,'May 2025'!K:K) -> L-6
A6: 5 | B6: 5 | C6: Rizwan Ali Khan | D6: On record | E6: Executive | F6: =_xlfn.XLOOKUP(B6,'May 2025'!B:B,'June 2025'!F:F) -> Domestic | G6: 41950 | H6: 40150 | I6: 1950 | J6: 0 | K6: =_xlfn.XLOOKUP(B6,'May 2025'!B:B,'May 2025'!K:K) -> L-6
A7: 6 | B7: 6 | C7: Tehseenul Islam Siddque | D7: On record | E7: Merchandiser | F7: =_xlfn.XLOOKUP(B7,'May 2025'!B:B,'June 2025'!F:F) -> Admin | G7: 62500 | H7: 62500 | I7: 0 | J7: 0 | K7: =_xlfn.XLOOKUP(B7,'May 2025'!B:B,'May 2025'!K:K) -> L-5
A8: 7 | B8: 7 | C8: Rajendra Prasad Vijay | D8: On record | E8: Senior Accountant | F8: =_xlfn.XLOOKUP(B8,'May 2025'!B:B,'June 2025'!F:F) -> Admin | G8: 48000 | H8: 48000 | I8: 0 | J8: 0 | K8: =_xlfn.XLOOKUP(B8,'May 2025'!B:B,'May 2025'!K:K) -> L-5
A9: 8 | B9: 8 | C9: Pankaj | D9: On record | E9: Final Checker | F9: =_xlfn.XLOOKUP('April 2025'!C9,'January 2025'!C:C,'January 2025'!F:F) -> Manufacturing | G9: 18225 | H9: 16775.8 | I9: 1422 | J9: 593 | K9: L-9
A10: 9 | B10: 9 | C10: Ravi Panchal | D10: On record | E10: SKU checker | F10: =_xlfn.XLOOKUP(B10,'May 2025'!B:B,'June 2025'!F:F) -> Domestic | G10: 14800 | H10: 13613.8 | I10: 1165 | J10: 481 | K10: =_xlfn.XLOOKUP(B10,'May 2025'!B:B,'May 2025'!K:K) -> L-9
A11: 10 | B11: 10 | C11: Chandrakanta Meher | D11: On record | E11: Executive | F11: =_xlfn.XLOOKUP('April 2025'!C11,'January 2025'!C:C,'January 2025'!F:F) -> Manufacturing | G11: 34300 | H11: 34300 | I11: 0 | J11: 0 | K11: L-8
A12: 11 | B12: 11 | C12: Rupesh Kumar Jha | D12: On record | E12: Jr. Accountant | F12: =_xlfn.XLOOKUP(B12,'May 2025'!B:B,'June 2025'!F:F) -> Admin | G12: 22000 | H12: 20200 | I12: 1950 | J12: 0 | K12: =_xlfn.XLOOKUP(B12,'May 2025'!B:B,'May 2025'!K:K) -> L-6
A13: 12 | B13: 16 | C13: Abhishek Saini | D13: On record | E13: HR Manager | F13: =_xlfn.XLOOKUP(B13,'May 2025'!B:B,'June 2025'!F:F) -> Domestic | G13: 29000 | H13: 29000 | I13: 0 | J13: 0 | K13: =_xlfn.XLOOKUP(B13,'May 2025'!B:B,'May 2025'!K:K) -> L-9
A14: 13 | B14: 13 | C14: Lokesh Sharma | D14: On record | E14: Executive | F14: =_xlfn.XLOOKUP(B14,'May 2025'!B:B,'June 2025'!F:F) -> Domestic | G14: 14500 | H14: 13341 | I14: 1138 | J14: 472 | K14: =_xlfn.XLOOKUP(B14,'May 2025'!B:B,'May 2025'!K:K) -> L-7
A15: 14 | B15: 14 | C15: Rajesh Sharma | D15: On record | E15: Office Boy | F15: =_xlfn.XLOOKUP(B15,'May 2025'!B:B,'June 2025'!F:F) -> Office Support | G15: 15400 | H15: 14175.2 | I15: 1201 | J15: 501 | K15: =_xlfn.XLOOKUP(B15,'May 2025'!B:B,'May 2025'!K:K) -> L-10
A16: 15 | B16: 15 | C16: Yashodatt Sharma | D16: On record | E16: Fabric Checker | F16: =_xlfn.XLOOKUP(B16,'May 2025'!B:B,'June 2025'!F:F) -> Manufacturing | G16: 20000 | H16: 18410 | I16: 1560 | J16: 650 | K16: =_xlfn.XLOOKUP(B16,'May 2025'!B:B,'May 2025'!K:K) -> L-9
A17: 16 | B17: 16 | C17: Omprakash Yogi | D17: On record | E17: Checker | F17: =_xlfn.XLOOKUP(B17,'May 2025'!B:B,'June 2025'!F:F) -> Domestic | G17: 14063 | H17: 12775.708 | I17: 1280 | J17: 458 | K17: =_xlfn.XLOOKUP(B17,'May 2025'!B:B,'May 2025'!K:K) -> L-9
A18: 17 | B18: 17 | C18: Naveen Bhaskar | D18: On record | E18: Final Checker | F18: =_xlfn.XLOOKUP(B18,'May 2025'!B:B,'June 2025'!F:F) -> Manufacturing | G18: 17500 | H18: 16108 | I18: 1365 | J18: 569 | K18: =_xlfn.XLOOKUP(B18,'May 2025'!B:B,'May 2025'!K:K) -> L-9
A19: 18 | B19: 18 | C19: Surendra K. Bairwa | D19: On record | E19: Executive | F19: =_xlfn.XLOOKUP('April 2025'!C19,'January 2025'!C:C,'January 2025'!F:F) -> Manufacturing | G19: 17000 | H19: 15648 | I19: 1326 | J19: 553 | K19: L-8
A20: 19 | B20: 19 | C20: Govind Sharma | D20: On record | E20: Checker | F20: =_xlfn.XLOOKUP(B20,'May 2025'!B:B,'June 2025'!F:F) -> Manufacturing | G20: 15300 | H20: 14083.4 | I20: 1193 | J20: 498 | K20: =_xlfn.XLOOKUP(B20,'May 2025'!B:B,'May 2025'!K:K) -> L-9
A21: 20 | B21: 20 | C21: Naresh Kumar Bairwa | D21: On record | E21: Checker | F21: =_xlfn.XLOOKUP(B21,'May 2025'!B:B,'June 2025'!F:F) -> Manufacturing | G21: 14500 | H21: 13173 | I21: 1320 | J21: 472 | K21: =_xlfn.XLOOKUP(B21,'May 2025'!B:B,'May 2025'!K:K) -> L-9
A22: 21 | B22: 21 | C22: Sonu Bairwa | D22: On record | E22: Supervisior | F22: =_xlfn.XLOOKUP(B22,'May 2025'!B:B,'June 2025'!F:F) -> Manufacturing | G22: 22000 | H22: 20416 | I22: 1716 | J22: 0 | K22: =_xlfn.XLOOKUP(B22,'May 2025'!B:B,'May 2025'!K:K) -> L-8
A23: 22 | B23: 22 | C23: Faizal Rangrej | D23: On record | E23: Manager | F23: =_xlfn.XLOOKUP(B23,'May 2025'!B:B,'June 2025'!F:F) -> Domestic | G23: 68200 | H23: 66400 | I23: 1950 | J23: 0 | K23: =_xlfn.XLOOKUP(B23,'May 2025'!B:B,'May 2025'!K:K) -> L-5
A24: 23 | B24: 23 | C24: Anil Kumar | D24: On record | E24: Cutting Master | F24: =_xlfn.XLOOKUP('April 2025'!C24,'January 2025'!C:C,'January 2025'!F:F) -> Manufacturing | G24: 26000 | H24: 24284 | I24: 1859 | J24: 0 | K24: L-9
A25: 24 | B25: 24 | C25: Ravi Kumar Bairwa (Tatawat) | D25: On record | E25: Executive | F25: =_xlfn.XLOOKUP(B25,'May 2025'!B:B,'June 2025'!F:F) -> Domestic | G25: 14000 | H25: 12702.2 | I25: 1292 | J25: 455 | K25: =_xlfn.XLOOKUP(B25,'May 2025'!B:B,'May 2025'!K:K) -> L-8
A26: 25 | B26: 30 | C26: Chandra Shekhar Sharma | D26: On record | E26: Supervisior | F26: =_xlfn.XLOOKUP('April 2025'!C26,'January 2025'!C:C,'January 2025'!F:F) -> Manufacturing | G26: 28000 | H26: 28000 | I26: 0 | J26: 0 | K26: L-8
A27: 26 | B27: 31 | C27: Nupur Pawar | D27: On record | E27: Textile Designer | F27: =_xlfn.XLOOKUP('April 2025'!C27,'January 2025'!C:C,'January 2025'!F:F) -> D2C | G27: 40000 | H27: 40000 | I27: 0 | J27: 0 | K27: L-6
A28: 27 | B28: 27 | C28: Asim Shoyab Khan | D28: On record | E28: Executive | F28: =_xlfn.XLOOKUP(B28,'May 2025'!B:B,'June 2025'!F:F) -> Domestic | G28: 20625 | H28: 18737.44 | I28: 1877 | J28: 671 | K28: =_xlfn.XLOOKUP(B28,'May 2025'!B:B,'May 2025'!K:K) -> L-6
A29: 28 | B29: 33 | C29: Amit Pareek | D29: On record | E29: Manager | F29: =_xlfn.XLOOKUP(B29,'May 2025'!B:B,'June 2025'!F:F) -> D2C | G29: 80000 | H29: 78200 | I29: 1950 | J29: 0 | K29: =_xlfn.XLOOKUP(B29,'May 2025'!B:B,'May 2025'!K:K) -> L-6
A30: 29 | B30: 29 | C30: Peeyush Pareek | D30: On record | E30: Manager | F30: =_xlfn.XLOOKUP(B30,'May 2025'!B:B,'June 2025'!F:F) -> D2C | G30: 79450 | H30: 77650 | I30: 1950 | J30: 0 | K30: =_xlfn.XLOOKUP(B30,'May 2025'!B:B,'May 2025'!K:K) -> L-5
A31: 30 | B31: 19 | C31: Rahul Yogi | D31: On record | E31: Helper | F31: =_xlfn.XLOOKUP(B31,'May 2025'!B:B,'June 2025'!F:F) -> Manufacturing | G31: 11000 | H31: 9837 | I31: 1170 | J31: 358 | K31: =_xlfn.XLOOKUP(B31,'May 2025'!B:B,'May 2025'!K:K) -> L-9
A32: 31 | B32: 31 | C32: Bheema Ram Bairwa | D32: On record | E32: Computer Operator | F32: =_xlfn.XLOOKUP('April 2025'!C32,'January 2025'!C:C,'January 2025'!F:F) -> Manufacturing | G32: 15000 | H32: 13663 | I32: 1326 | J32: 488 | K32: L-7
A33: 32 | B33: 32 | C33: Shaitan Singh | D33: On record | E33: Supervisior | F33: =_xlfn.XLOOKUP(B33,'May 2025'!B:B,'June 2025'!F:F) -> Manufacturing | G33: 25000 | H33: 25000 | I33: 0 | J33: 0 | K33: =_xlfn.XLOOKUP(B33,'May 2025'!B:B,'May 2025'!K:K) -> L-8
A34: 33 | B34: 33 | C34: Chakshita Maheshwari | D34: On record | E34: Graphic Designer | F34: =_xlfn.XLOOKUP(B34,'May 2025'!B:B,'June 2025'!F:F) -> D2C | G34: 37000 | H34: 37000 | I34: 0 | J34: 0 | K34: =_xlfn.XLOOKUP(B34,'May 2025'!B:B,'May 2025'!K:K) -> L-6
A35: 34 | B35: 37 | C35: Yuvraj Singh Sisodiya | D35: On record | E35: Supervisior | F35: =_xlfn.XLOOKUP(B35,'May 2025'!B:B,'June 2025'!F:F) -> Overseas | G35: 18000 | H35: 16353 | I35: 1638 | J35: 585 | K35: =_xlfn.XLOOKUP(B35,'May 2025'!B:B,'May 2025'!K:K) -> L-6
A36: 35 | B36: 35 | C36: Sumer singh Jatav | D36: On record | E36: Press man | F36: =_xlfn.XLOOKUP('April 2025'!C36,'January 2025'!C:C,'January 2025'!F:F) -> Manufacturing | G36: 13500 | H36: 12264 | I36: 1229 | J36: 439 | K36: L-9
A37: 36 | B37: 39 | C37: Ashok Yogi | D37: On record | E37: Checker | F37: =_xlfn.XLOOKUP(B37,'May 2025'!B:B,'June 2025'!F:F) -> Manufacturing | G37: 12500 | H37: 11356 | I37: 1138 | J37: 407 | K37: =_xlfn.XLOOKUP(B37,'May 2025'!B:B,'May 2025'!K:K) -> L-9
A38: 37 | B38: 37 | C38: Karishma Kaityar | D38: On record | E38: Senior Executive | F38: =_xlfn.XLOOKUP(B38,'May 2025'!B:B,'June 2025'!F:F) -> Overseas | G38: 40000 | H38: 40000 | I38: 0 | J38: 0 | K38: =_xlfn.XLOOKUP(B38,'May 2025'!B:B,'May 2025'!K:K) -> L-6
A39: 38 | B39: 38 | C39: Surajmal Prajapati | D39: On record | E39: Human Resource | F39: =_xlfn.XLOOKUP(B39,'May 2025'!B:B,'June 2025'!F:F) -> Admin | G39: 41000 | H39: 41000 | I39: 0 | J39: 0 | K39: =_xlfn.XLOOKUP(B39,'May 2025'!B:B,'May 2025'!K:K) -> L-5
A40: 39 | B40: 39 | C40: Padmawati | D40: On record | E40: Tailor | F40: =_xlfn.XLOOKUP(B40,'May 2025'!B:B,'June 2025'!F:F) -> Manufacturing | G40: 30000 | H40: 30000 | I40: 0 | J40: 0 | K40: =_xlfn.XLOOKUP(B40,'May 2025'!B:B,'May 2025'!K:K) -> L-9
...

Sheet May 2025
A1: Sr. No. | B1: User ID | C1: Emp. Name | D1: Mode | E1: Designation | F1: Department | G1: Gross salary | H1: In Hand Salary | I1: PF Employer | J1: ESI Employer | K1: Level Wise
A2: 1 | B2: 1 | C2: Chanda Ji | D2: On record | E2: Eyelet Marker | F2: =_xlfn.XLOOKUP(B2,'June 2025'!B:B,'June 2025'!F:F) -> Manufacturing | G2: 11000 | H2: 11000 | I2: 858 | J2: 358 | K2: L-9
A3: 2 | B3: 2 | C3: Surendra Bairwa | D3: On record | E3: Executive | F3: =_xlfn.XLOOKUP(B3,'June 2025'!B:B,'June 2025'!F:F) -> Domestic | G3: 20500 | H3: 16202 | I3: 1264 | J3: 527 | K3: =_xlfn.XLOOKUP(B3,'June 2025'!B:B,'June 2025'!K:K) -> L-8
A4: 3 | B4: 3 | C4: Harkesh Kumar Bairwa | D4: On record | E4: Cutting Master | F4: =_xlfn.XLOOKUP(B4,'June 2025'!B:B,'June 2025'!F:F) -> Manufacturing | G4: 27500 | H4: 25726 | I4: 0 | J4: 0 | K4: =_xlfn.XLOOKUP(B4,'June 2025'!B:B,'June 2025'!K:K) -> L-9
A5: 4 | B5: 4 | C5: Mohd. Shoyeb Rangrej | D5: On record | E5: Executive | F5: =_xlfn.XLOOKUP(B5,'June 2025'!B:B,'June 2025'!F:F) -> Domestic | G5: 25781 | H5: 25781 | I5: 1950 | J5: 0 | K5: =_xlfn.XLOOKUP(B5,'June 2025'!B:B,'June 2025'!K:K) -> L-6
A6: 5 | B6: 5 | C6: Rizwan Ali Khan | D6: On record | E6: Executive | F6: =_xlfn.XLOOKUP(B6,'June 2025'!B:B,'June 2025'!F:F) -> Domestic | G6: 41950 | H6: 41950 | I6: 1950 | J6: 0 | K6: =_xlfn.XLOOKUP(B6,'June 2025'!B:B,'June 2025'!K:K) -> L-6
A7: 6 | B7: 6 | C7: Tehseenul Islam Siddque | D7: On record | E7: Merchandiser | F7: =_xlfn.XLOOKUP(B7,'June 2025'!B:B,'June 2025'!F:F) -> Admin | G7: 62500 | H7: 62500 | I7: 0 | J7: 0 | K7: =_xlfn.XLOOKUP(B7,'June 2025'!B:B,'June 2025'!K:K) -> L-5
A8: 7 | B8: 7 | C8: Rajendra Prasad Vijay | D8: On record | E8: Senior Accountant | F8: =_xlfn.XLOOKUP(B8,'June 2025'!B:B,'June 2025'!F:F) -> Admin | G8: 48000 | H8: 48000 | I8: 0 | J8: 0 | K8: =_xlfn.XLOOKUP(B8,'June 2025'!B:B,'June 2025'!K:K) -> L-5
A9: 8 | B9: 9 | C9: Ravi Panchal | D9: On record | E9: SKU checker | F9: =_xlfn.XLOOKUP(B9,'June 2025'!B:B,'June 2025'!F:F) -> Domestic | G9: 14800 | H9: 14323 | I9: 1127 | J9: 466 | K9: =_xlfn.XLOOKUP(B9,'June 2025'!B:B,'June 2025'!K:K) -> L-9
A10: 9 | B10: 11 | C10: Rupesh Kumar Jha | D10: On record | E10: Jr. Accountant | F10: =_xlfn.XLOOKUP(B10,'June 2025'!B:B,'June 2025'!F:F) -> Admin | G10: 22000 | H10: 19161 | I10: 1744 | J10: 0 | K10: =_xlfn.XLOOKUP(B10,'June 2025'!B:B,'June 2025'!K:K) -> L-6
A11: 10 | B11: 13 | C11: Lokesh Sharma | D11: On record | E11: Executive | F11: =_xlfn.XLOOKUP(B11,'June 2025'!B:B,'June 2025'!F:F) -> Domestic | G11: 14500 | H11: 12629 | I11: 991 | J11: 411 | K11: =_xlfn.XLOOKUP(B11,'June 2025'!B:B,'June 2025'!K:K) -> L-7
A12: 11 | B12: 14 | C12: Rajesh Sharma | D12: On record | E12: Office Boy | F12: =_xlfn.XLOOKUP(B12,'June 2025'!B:B,'June 2025'!F:F) -> Office Support | G12: 15400 | H12: 15400 | I12: 1201 | J12: 501 | K12: =_xlfn.XLOOKUP(B12,'June 2025'!B:B,'June 2025'!K:K) -> L-10
A13: 12 | B13: 15 | C13: Yashodatt Sharma | D13: On record | E13: Fabric Checker | F13: =_xlfn.XLOOKUP(B13,'June 2025'!B:B,'June 2025'!F:F) -> Manufacturing | G13: 20000 | H13: 18710 | I13: 1459 | J13: 609 | K13: =_xlfn.XLOOKUP(B13,'June 2025'!B:B,'June 2025'!K:K) -> L-9
A14: 13 | B14: 16 | C14: Omprakash Yogi | D14: On record | E14: Checker | F14: =_xlfn.XLOOKUP(B14,'June 2025'!B:B,'June 2025'!F:F) -> Domestic | G14: 14063 | H14: 6804 | I14: 619 | J14: 222 | K14: =_xlfn.XLOOKUP(B14,'June 2025'!B:B,'June 2025'!K:K) -> L-9
... A37: 36 | B37: 10004 | C37: Ramswaroop | D37: Console | E37: Final Checker | F37: =_xlfn.XLOOKUP(B37,'June 2025'!B:B,'June 2025'!F:F) -> Manufacturing | G37: 17000 | H37: 13710 | I37: 0 | J37: 0 | K37: =_xlfn.XLOOKUP(B37,'June 2025'!B:B,'June 2025'!K:K) -> L-9
A38: 37 | B38: 10005 | C38: Chhaju Lal Saini | D38: Console | E38: Computer Operator | F38: Domestic | G38: 17000 | H38: 12613 | I38: 0 | J38: 0 | K38: L-8
A39: 38 | B39: 10006 | C39: Mahendra Gurjer | D39: Console | E39: Cutting Master | F39: Manufacturing | G39: 16000 | H39: 11355 | I39: 0 | J39: 0 | K39: L-9
A40: 39 | B40: 10007 | C40: Jitendra Sharma | D40: Console | E40: Executive | F40: Domestic | G40: 15000 | H40: 13548 | I40: 0 | J40: 0 | K40: L-8
A41: 40 | B41: 10008 | C41: Santara | D41: Console | E41: SWEEPER | F41: =_xlfn.XLOOKUP(B41,'June 2025'!B:B,'June 2025'!F:F) -> Office Support | G41: 11000 | H41: 11000 | I41: 0 | J41: 0 | K41: =_xlfn.XLOOKUP(B41,'June 2025'!B:B,'June 2025'!K:K) -> L-10
A42: 41 | B42: 10009 | C42: Rohitash Kumar | D42: Console | E42: Helper | F42: Manufacturing | G42: 11500 | H42: 0 | I42: 0 | J42: 0 | K42: L-10
A43: 42 | B43: 10012 | C43: Ramavtar sharma | D43: Security Contractor | E43: Guard | F43: =_xlfn.XLOOKUP(B43,'June 2025'!B:B,'June 2025'!F:F) -> Office Support | G43: 14000 | H43: 0 | I43: 0 | J43: 0 | K43: =_xlfn.XLOOKUP(B43,'June 2025'!B:B,'June 2025'!K:K) -> L-10
A44: 43 | B44: 10013 | C44: Jitendra Bairwa | D44: Console | E44: Executive | F44: Domestic | G44: 13500 | H44: 12629 | I44: 0 | J44: 0 | K44: L-8
A45: 44 | B45: 10014 | C45: Vikash Bairwa | D45: Console | E45: Helper | F45: =_xlfn.XLOOKUP(B45,'June 2025'!B:B,'June 2025'!F:F) -> Manufacturing | G45: 12000 | H45: 10065 | I45: 0 | J45: 0 | K45: =_xlfn.XLOOKUP(B45,'June 2025'!B:B,'June 2025'!K:K) -> L-10
A46: 45 | B46: 10015 | C46: Asharam Bairwa | D46: Console | E46: Checker | F46: =_xlfn.XLOOKUP(B46,'June 2025'!B:B,'June 2025'!F:F) -> Manufacturing | G46: 14000 | H46: 7677 | I46: 0 | J46: 0 | K46: =_xlfn.XLOOKUP(B46,'June 2025'!B:B,'June 2025'!K:K) -> L-9
A47: 46 | B47: 10016 | C47: Manjeet Sain | D47: Console | E47: Executive | F47: Overseas | G47: 13500 | H47: 11758 | I47: 0 | J47: 0 | K47: L-8
A48: 47 | B48: 10017 | C48: Mohan lal Bairwa | D48: Console | E48: Helper | F48: =_xlfn.XLOOKUP(B48,'June 2025'!B:B,'June 2025'!F:F) -> Manufacturing | G48: 13000 | H48: 7548 | I48: 0 | J48: 0 | K48: =_xlfn.XLOOKUP(B48,'June 2025'!B:B,'June 2025'!K:K) -> L-10
A49: 48 | B49: 10018 | C49: Rahul Bairwa | D49: Console | E49: Checker | F49: =_xlfn.XLOOKUP(B49,'June 2025'!B:B,'June 2025'!F:F) -> Manufacturing | G49: 15700 | H49: 14180 | I49: 0 | J49: 0 | K49: =_xlfn.XLOOKUP(B49,'June 2025'!B:B,'June 2025'!K:K) -> L-9
A50: 49 | B50: 10020 | C50: Raju Lal Bairwa | D50: Console | E50: Checker | F50: =_xlfn.XLOOKUP(B50,'June 2025'!B:B,'June 2025'!F:F) -> Manufacturing | G50: 14500 | H50: 12863 | I50: 0 | J50: 0 | K50: =_xlfn.XLOOKUP(B50,'June 2025'!B:B,'June 2025'!K:K) -> L-9
A51: 50 | B51: 10021 | C51: Kaptaan Singh | D51: Console | E51: Checker | F51: =_xlfn.XLOOKUP(B51,'June 2025'!B:B,'June 2025'!F:F) -> Manufacturing | G51: 14200 | H51: 8245 | I51: 0 | J51: 0 | K51: =_xlfn.XLOOKUP(B51,'June 2025'!B:B,'June 2025'!K:K) -> L-9
A52: 51 | B52: 10027 | C52: Mahendra Sharma | D52: Console | E52: Senior Executive | F52: =_xlfn.XLOOKUP(B52,'June 2025'!B:B,'June 2025'!F:F) -> Domestic | G52: 6500 | H52: 5452 | I52: 0 | J52: 0 | K52: =_xlfn.XLOOKUP(B52,'June 2025'!B:B,'June 2025'!K:K) -> L-7
A53: 52 | B53: 10036 | C53: Surendra Tailor | D53: Console | E53: Checker | F53: =_xlfn.XLOOKUP(B53,'June 2025'!B:B,'June 2025'!F:F) -> Manufacturing | G53: 14500 | H53: 14032 | I53: 0 | J53: 0 | K53: =_xlfn.XLOOKUP(B53,'June 2025'!B:B,'June 2025'!K:K) -> L-9
A54: 53 | B54: 10037 | C54: Feliram Bairwa | D54: Console | E54: Checker | F54: =_xlfn.XLOOKUP(B54,'June 2025'!B:B,'June 2025'!F:F) -> Manufacturing | G54: 15000 | H54: 14516 | I54: 0 | J54: 0 | K54: =_xlfn.XLOOKUP(B54,'June 2025'!B:B,'June 2025'!K:K) -> L-9
A55: 54 | B55: 10041 | C55: Vikash Kumar | D55: Console | E55: Checker | F55: =_xlfn.XLOOKUP(B55,'June 2025'!B:B,'June 2025'!F:F) -> Manufacturing | G55: 14000 | H55: 10838 | I55: 0 | J55: 0 | K55: =_xlfn.XLOOKUP(B55,'June 2025'!B:B,'June 2025'!K:K) -> L-9
A56: 55 | B56: 10043 | C56: Ehsaan Khan | D56: Console | E56: Checker | F56: =_xlfn.XLOOKUP(B56,'June 2025'!B:B,'June 2025'!F:F) -> Domestic | G56: 13500 | H56: 8275 | I56: 0 | J56: 0 | K56: =_xlfn.XLOOKUP(B56,'June 2025'!B:B,'June 2025'!K:K) -> L-9
A57: 56 | B57: 10046 | C57: Suresh Sharma | D57: Console | E57: Computer Operator | F57: Domestic | G57: 16500 | H57: 16500 | I57: 0 | J57: 0 | K57: L-7
A58: 57 | B58: 10049 | C58: Mithta Lal Bairwa | D58: Console | E58: Helper | F58: =_xlfn.XLOOKUP(B58,'June 2025'!B:B,'June 2025'!F:F) -> Domestic | G58: 13000 | H58: 7339 | I58: 0 | J58: 0 | K58: =_xlfn.XLOOKUP(B58,'June 2025'!B:B,'June 2025'!K:K) -> L-10
A59: 58 | B59: 10050 | C59: Upendra Bairwa | D59: Console | E59: Helper | F59: Manufacturing | G59: 11000 | H59: 0 | I59: 0 | J59: 0 | K59: L-10
A60: 59 | B60: 10053 | C60: Hanuman Sahay Prajapat | D60: Console | E60: Computer Operator | F60: Manufacturing | G60: 13000 | H60: 9435 | I60: 0 | J60: 0 | K60: L-7
A61: 60 | B61: 10054 | C61: Pawan Prajapat | D61: Console | E61: Computer Operator | F61: Domestic | G61: 14500 | H61: 13798 | I61: 0 | J61: 0 | K61: L-7
A62: 61 | B62: 10055 | C62: Jabid Husen | D62: Console | E62: Helper | F62: =_xlfn.XLOOKUP(B62,'June 2025'!B:B,'June 2025'!F:F) -> Domestic | G62: 11000 | H62: 10290 | I62: 0 | J62: 0 | K62: =_xlfn.XLOOKUP(B62,'June 2025'!B:B,'June 2025'!K:K) -> L-10
...

Sheet June 2025
A1: Sr. No. | B1: User ID | C1: Emp. Name | D1: Mode | E1: Designation | F1: Department | G1: Gross salary | H1: In Hand Salary | I1: PF Employer | J1: ESI Employer | K1: Level Wise
A2: 1 | B2: 1 | C2: Chanda Ji | D2: On record | E2: Eyelet Marker | F2: =_xlfn.XLOOKUP(B2,'July 2025'!B:B,'July 2025'!F:F) -> Manufacturing | G2: 11000 | H2: 0 | I2: 0 | J2: 0 | K2: =_xlfn.XLOOKUP(B2,'July 2025'!B:B,'July 2025'!K:K) -> L-9
A3: 2 | B3: 2 | C3: Surendra Bairwa | D3: On record | E3: Executive | F3: =_xlfn.XLOOKUP(B3,'July 2025'!B:B,'July 2025'!F:F) -> Domestic | G3: 20500 | H3: 17425 | I3: 1359 | J3: 567 | K3: =_xlfn.XLOOKUP(B3,'July 2025'!B:B,'July 2025'!K:K) -> L-8
A4: 3 | B4: 3 | C4: Harkesh Kumar Bairwa | D4: On record | E4: Cutting Master | F4: =_xlfn.XLOOKUP(B4,'July 2025'!B:B,'July 2025'!F:F) -> Manufacturing | G4: 27500 | H4: 24751 | I4: 0 | J4: 0 | K4: =_xlfn.XLOOKUP(B4,'July 2025'!B:B,'July 2025'!K:K) -> L-9
A5: 4 | B5: 4 | C5: Mohd. Shoyeb Rangrej | D5: On record | E5: Executive | F5: =_xlfn.XLOOKUP(B5,'July 2025'!B:B,'July 2025'!F:F) -> Domestic | G5: 25781 | H5: 25781 | I5: 1950 | J5: 0 | K5: =_xlfn.XLOOKUP(B5,'July 2025'!B:B,'July 2025'!K:K) -> L-6
A6: 5 | B6: 5 | C6: Rizwan Ali Khan | D6: On record | E6: Executive | F6: =_xlfn.XLOOKUP(B6,'July 2025'!B:B,'July 2025'!F:F) -> Domestic | G6: 41950 | H6: 41950 | I6: 1950 | J6: 0 | K6: =_xlfn.XLOOKUP(B6,'July 2025'!B:B,'July 2025'!K:K) -> L-6
A7: 6 | B7: 6 | C7: Tehseenul Islam Siddque | D7: On record | E7: Merchandiser | F7: =_xlfn.XLOOKUP(B7,'July 2025'!B:B,'July 2025'!F:F) -> Admin | G7: 62500 | H7: 62500 | I7: 0 | J7: 0 | K7: =_xlfn.XLOOKUP(B7,'July 2025'!B:B,'July 2025'!K:K) -> L-5
A8: 7 | B8: 7 | C8: Rajendra Prasad Vijay | D8: On record | E8: Senior Accountant | F8: =_xlfn.XLOOKUP(B8,'July 2025'!B:B,'July 2025'!F:F) -> Admin | G8: 48000 | H8: 48000 | I8: 0 | J8: 0 | K8: =_xlfn.XLOOKUP(B8,'July 2025'!B:B,'July 2025'!K:K) -> L-5
A9: 8 | B9: 9 | C9: Ravi Panchal | D9: On record | E9: SKU checker | F9: =_xlfn.XLOOKUP(B9,'July 2025'!B:B,'July 2025'!F:F) -> Domestic | G9: 16300 | H9: 13040 | I9: 1017 | J9: 424 | K9: =_xlfn.XLOOKUP(B9,'July 2025'!B:B,'July 2025'!K:K) -> L-9
A10: 9 | B10: 11 | C10: Rupesh Kumar Jha | D10: On record | E10: Jr. Accountant | F10: =_xlfn.XLOOKUP(B10,'July 2025'!B:B,'July 2025'!F:F) -> Admin | G10: 22000 | H10: 22000 | I10: 1950 | J10: 0 | K10: =_xlfn.XLOOKUP(B10,'July 2025'!B:B,'July 2025'!K:K) -> L-6
A11: 10 | B11: 13 | C11: Lokesh Sharma | D11: On record | E11: Executive | F11: =_xlfn.XLOOKUP(B11,'July 2025'!B:B,'July 2025'!F:F) -> Domestic | G11: 16000 | H11: 14133 | I11: 1102 | J11: 460 | K11: =_xlfn.XLOOKUP(B11,'July 2025'!B:B,'July 2025'!K:K) -> L-7
A12: 11 | B12: 14 | C12: Rajesh Sharma | D12: On record | E12: Office Boy | F12: =_xlfn.XLOOKUP(B12,'July 2025'!B:B,'July 2025'!F:F) -> Office Support | G12: 15400 | H12: 15400 | I12: 1201 | J12: 501 | K12: =_xlfn.XLOOKUP(B12,'July 2025'!B:B,'July 2025'!K:K) -> L-10
A13: 12 | B13: 15 | C13: Yashodatt Sharma | D13: On record | E13: Fabric Checker | F13: =_xlfn.XLOOKUP(B13,'July 2025'!B:B,'July 2025'!F:F) -> Manufacturing | G13: 20000 | H13: 18333 | I13: 1430 | J13: 596 | K13: =_xlfn.XLOOKUP(B13,'July 2025'!B:B,'July 2025'!K:K) -> L-9
... A15: 14 | B15: 17 | C15: Naveen Bhaskar | D15: On record | E15: Final Checker | F15: =_xlfn.XLOOKUP(B15,'July 2025'!B:B,'July 2025'!F:F) -> Manufacturing | G15: 17500 | H15: 17500 | I15: 1365 | J15: 569 | K15: =_xlfn.XLOOKUP(B15,'July 2025'!B:B,'July 2025'!K:K) -> L-9
A16: 15 | B16: 19 | C16: Govind Sharma | D16: On record | E16: Checker | F16: Manufacturing | G16: 15300 | H16: 6885 | I16: 537 | J16: 224 | K16: L-9
A17: 16 | B17: 20 | C17: Naresh Kumar Bairwa | D17: On record | E17: Checker | F17: =_xlfn.XLOOKUP(B17,'July 2025'!B:B,'July 2025'!F:F) -> Manufacturing | G17: 14500 | H17: 14500 | I17: 1320 | J17: 472 | K17: =_xlfn.XLOOKUP(B17,'July 2025'!B:B,'July 2025'!K:K) -> L-9
A18: 17 | B18: 21 | C18: Sonu Bairwa | D18: On record | E18: Supervisior | F18: =_xlfn.XLOOKUP(B18,'July 2025'!B:B,'July 2025'!F:F) -> Manufacturing | G18: 22000 | H18: 20533 | I18: 1602 | J18: 0 | K18: =_xlfn.XLOOKUP(B18,'July 2025'!B:B,'July 2025'!K:K) -> L-8
A19: 18 | B19: 22 | C19: Faizal Rangrej | D19: On record | E19: Manager | F19: =_xlfn.XLOOKUP(B19,'July 2025'!B:B,'July 2025'!F:F) -> Domestic | G19: 68200 | H19: 68200 | I19: 1950 | J19: 0 | K19: =_xlfn.XLOOKUP(B19,'July 2025'!B:B,'July 2025'!K:K) -> L-5
A20: 19 | B20: 24 | C20: Ravi Kumar Bairwa (Tatawat) | D20: On record | E20: Executive | F20: =_xlfn.XLOOKUP(B20,'July 2025'!B:B,'July 2025'!F:F) -> Domestic | G20: 15500 | H20: 7234 | I20: 668 | J20: 236 | K20: =_xlfn.XLOOKUP(B20,'July 2025'!B:B,'July 2025'!K:K) -> L-8
A21: 20 | B21: 27 | C21: Asim Shoyab Khan | D21: On record | E21: Executive | F21: =_xlfn.XLOOKUP(B21,'July 2025'!B:B,'July 2025'!F:F) -> Domestic | G21: 25988 | H21: 25122 | I21: 1950 | J21: 0 | K21: =_xlfn.XLOOKUP(B21,'July 2025'!B:B,'July 2025'!K:K) -> L-6
A22: 21 | B22: 29 | C22: Peeyush Pareek | D22: On record | E22: Manager | F22: =_xlfn.XLOOKUP(B22,'July 2025'!B:B,'July 2025'!F:F) -> D2C | G22: 79450 | H22: 79450 | I22: 1950 | J22: 0 | K22: =_xlfn.XLOOKUP(B22,'July 2025'!B:B,'July 2025'!K:K) -> L-5
A23: 22 | B23: 32 | C23: Shaitan Singh | D23: On record | E23: Supervisior | F23: =_xlfn.XLOOKUP(B23,'July 2025'!B:B,'July 2025'!F:F) -> Manufacturing | G23: 25000 | H23: 24167 | I23: 0 | J23: 0 | K23: =_xlfn.XLOOKUP(B23,'July 2025'!B:B,'July 2025'!K:K) -> L-8
A24: 23 | B24: 33 | C24: Chakshita Maheshwari | D24: On record | E24: Graphic Designer | F24: =_xlfn.XLOOKUP(B24,'July 2025'!B:B,'July 2025'!F:F) -> D2C | G24: 37000 | H24: 41177 | I24: 0 | J24: 0 | K24: =_xlfn.XLOOKUP(B24,'July 2025'!B:B,'July 2025'!K:K) -> L-6
A25: 24 | B25: 37 | C25: Karishma Kaityar | D25: On record | E25: Senior Executive | F25: =_xlfn.XLOOKUP(B25,'July 2025'!B:B,'July 2025'!F:F) -> Overseas | G25: 44000 | H25: 44000 | I25: 0 | J25: 0 | K25: =_xlfn.XLOOKUP(B25,'July 2025'!B:B,'July 2025'!K:K) -> L-6
A26: 25 | B26: 38 | C26: Surajmal Prajapati | D26: On record | E26: Human Resource | F26: =_xlfn.XLOOKUP(B26,'July 2025'!B:B,'July 2025'!F:F) -> Admin | G26: 41000 | H26: 41000 | I26: 0 | J26: 0 | K26: =_xlfn.XLOOKUP(B26,'July 2025'!B:B,'July 2025'!K:K) -> L-5
A27: 26 | B27: 39 | C27: Padmawati | D27: On record | E27: Tailor | F27: =_xlfn.XLOOKUP(B27,'July 2025'!B:B,'July 2025'!F:F) -> Manufacturing | G27: 30000 | H27: 19000 | I27: 0 | J27: 0 | K27: =_xlfn.XLOOKUP(B27,'July 2025'!B:B,'July 2025'!K:K) -> L-9
A28: 27 | B28: 40 | C28: Foranti | D28: On record | E28: Tailor | F28: =_xlfn.XLOOKUP(B28,'July 2025'!B:B,'July 2025'!F:F) -> Manufacturing | G28: 30000 | H28: 19000 | I28: 0 | J28: 0 | K28: =_xlfn.XLOOKUP(B28,'July 2025'!B:B,'July 2025'!K:K) -> L-9
A29: 28 | B29: 41 | C29: Sonu Bairwa Tailor | D29: On record | E29: Tailor | F29: Manufacturing | G29: 30000 | H29: 0 | I29: 0 | J29: 0 | K29: L-9
A30: 29 | B30: 42 | C30: Raji Devi | D30: On record | E30: Tailor | F30: =_xlfn.XLOOKUP(B30,'July 2025'!B:B,'July 2025'!F:F) -> Manufacturing | G30: 30000 | H30: 12500 | I30: 0 | J30: 0 | K30: =_xlfn.XLOOKUP(B30,'July 2025'!B:B,'July 2025'!K:K) -> L-9
A31: 30 | B31: 43 | C31: Laxman | D31: On record | E31: Tailor | F31: =_xlfn.XLOOKUP(B31,'July 2025'!B:B,'July 2025'!F:F) -> Manufacturing | G31: 30000 | H31: 29500 | I31: 0 | J31: 0 | K31: =_xlfn.XLOOKUP(B31,'July 2025'!B:B,'July 2025'!K:K) -> L-9
A32: 31 | B32: 44 | C32: Dilip | D32: On record | E32: Tailor | F32: =_xlfn.XLOOKUP(B32,'July 2025'!B:B,'July 2025'!F:F) -> Manufacturing | G32: 30000 | H32: 16500 | I32: 0 | J32: 0 | K32: =_xlfn.XLOOKUP(B32,'July 2025'!B:B,'July 2025'!K:K) -> L-9
A33: 32 | B33: 46 | C33: Furqan Hameed | D33: On record | E33: Manager | F33: =_xlfn.XLOOKUP(B33,'July 2025'!B:B,'July 2025'!F:F) -> Overseas | G33: 80000 | H33: 80000 | I33: 0 | J33: 0 | K33: =_xlfn.XLOOKUP(B33,'July 2025'!B:B,'July 2025'!K:K) -> L-5
A34: 33 | B34: 48 | C34: Safina Khan | D34: On record | E34: Tailor | F34: =_xlfn.XLOOKUP(B34,'July 2025'!B:B,'July 2025'!F:F) -> Manufacturing | G34: 30000 | H34: 30000 | I34: 0 | J34: 0 | K34: =_xlfn.XLOOKUP(B34,'July 2025'!B:B,'July 2025'!K:K) -> L-9
A35: 34 | B35: 49 | C35: Gulbatti Meena | D35: On record | E35: Tailor | F35: =_xlfn.XLOOKUP(B35,'July 2025'!B:B,'July 2025'!F:F) -> Manufacturing | G35: 30000 | H35: 20500 | I35: 0 | J35: 0 | K35: =_xlfn.XLOOKUP(B35,'July 2025'!B:B,'July 2025'!K:K) -> L-9
A36: 35 | B36: 50 | C36: Ajay Singh Tiwari | D36: On record | E36: Executive | F36: =_xlfn.XLOOKUP(B36,'July 2025'!B:B,'July 2025'!F:F) -> Domestic | G36: 30000 | H36: 30000 | I36: 0 | J36: 0 | K36: =_xlfn.XLOOKUP(B36,'July 2025'!B:B,'July 2025'!K:K) -> L-6
A37: 36 | B37: 54 | C37: Mamta Saini | D37: On record | E37: Tailor | F37: =_xlfn.XLOOKUP(B37,'July 2025'!B:B,'July 2025'!F:F) -> Manufacturing | G37: 30000 | H37: 17500 | I37: 0 | J37: 0 | K37: =_xlfn.XLOOKUP(B37,'July 2025'!B:B,'July 2025'!K:K) -> L-9
A38: 37 | B38: 55 | C38: Mamta Sain | D38: On record | E38: Tailor | F38: =_xlfn.XLOOKUP(B38,'July 2025'!B:B,'July 2025'!F:F) -> Manufacturing | G38: 30000 | H38: 18500 | I38: 0 | J38: 0 | K38: =_xlfn.XLOOKUP(B38,'July 2025'!B:B,'July 2025'!K:K) -> L-9
A39: 38 | B39: 56 | C39: Shayari Saini | D39: On record | E39: Tailor | F39: =_xlfn.XLOOKUP(B39,'July 2025'!B:B,'July 2025'!F:F) -> Manufacturing | G39: 30000 | H39: 21500 | I39: 0 | J39: 0 | K39: =_xlfn.XLOOKUP(B39,'July 2025'!B:B,'July 2025'!K:K) -> L-9
A40: 39 | B40: 57 | C40: Jatin Arora | D40: On record | E40: Manager | F40: =_xlfn.XLOOKUP(B40,'July 2025'!B:B,'July 2025'!F:F) -> Overseas | G40: 48600 | H40: 48600 | I40: 1950 | J40: 0 | K40: =_xlfn.XLOOKUP(B40,'July 2025'!B:B,'July 2025'!K:K) -> L-6
A41: 40 | B41: 10002 | C41: Manish Kumar Bairwa | D41: Console | E41: Helper | F41: =_xlfn.XLOOKUP(B41,'July 2025'!B:B,'July 2025'!F:F) -> Domestic | G41: 15400 | H41: 11037 | I41: 0 | J41: 0 | K41: =_xlfn.XLOOKUP(B41,'July 2025'!B:B,'July 2025'!K:K) -> L-10
...

Sheet July 2025
A1: Sr. No. | B1: User ID | C1: Emp. Name | D1: Mode | E1: Designation | F1: Department | G1: Gross salary | H1: In Hand Salary | I1: PF Employer | J1: ESI Employer | K1: Level Wise
A2: 1 | B2: 1 | C2: Chanda Ji | D2: On record | E2: Eyelet Marker | F2: Manufacturing | G2: 11000 | H2: 6387 | I2: 498 | J2: 208 | K2: L-9
